<?xml version="1.0" ?>
<robot name="Part1" xmlns:xacro="http://www.ros.org/wiki/xacro">

    <xacro:property name="PI" value="3.14159" />
    <xacro:property name="effort" value="30.0" />
    <xacro:property name="velocity" value="10.0" />

    <xacro:macro name="default_inertial" params="mass">
        <inertial>
            <mass value="${mass}" />
            <inertia ixx="1.0" ixy="0.0" ixz="0.0"
                     iyy="1.0" iyz="0.0"
                     izz="1.0" />
        </inertial>
    </xacro:macro>


    <link name="base_footprint" />

    <link name="base_link">
        <xacro:default_inertial mass="1.0" />
        <visual>
            <geometry>
                <mesh filename="package://arm_urdf/meshes/Base_Plate_.stl" scale="0.01 0.01 0.01" />
            </geometry>
            <origin xyz="0 0 0" rpy="${PI/2} 0 0" />
        </visual>
        <collision>
            <geometry>
                <mesh filename="package://arm_urdf/meshes/Base_Plate_.stl" scale="0.01 0.01 0.01" />
            </geometry>
            <origin xyz="0 0 0" rpy="${PI/2} 0 0" />
        </collision>
    </link>

    <joint name="fixed_base_joint" type="fixed">
        <parent link="base_footprint" />
        <child link="base_link" />
        <origin xyz="0 0 0" rpy="0 0 0" />
    </joint>

    <link name="revolute_base_link">
        <xacro:default_inertial mass="1.0" />
        <visual>
            <geometry>
                <mesh filename="package://arm_urdf/meshes/Link1_.stl" scale="0.01 0.01 0.01" />
            </geometry>
            <origin xyz="0 0 -0.508" rpy="${PI/2} 0 0" />
        </visual>
        <collision>
            <geometry>
                <mesh filename="package://arm_urdf/meshes/Link1_.stl" scale="0.01 0.01 0.01" />
            </geometry>
            <origin xyz="0 0 -0.508" rpy="${PI/2} 0 0" />
        </collision>
    </link>

    <joint name="fixed_base_rev_base_joint" type="continuous">
        <parent link="base_link" />
        <child link="revolute_base_link" />
        <origin xyz="0 0 0.508" rpy="0 0 0" />
        <axis xyz="0 0 1" />
    </joint>

    <link name="link2">
        <xacro:default_inertial mass="1.0" />
        <visual>
            <geometry>
                <mesh filename="package://arm_urdf/meshes/Link2_.stl" scale="0.01 0.01 0.01" />
            </geometry>
            <origin xyz="0.098 0 -0.805" rpy="${PI/2} 0 0" />
        </visual>
        <collision>
            <geometry>
                <mesh filename="package://arm_urdf/meshes/Link2_.stl" scale="0.01 0.01 0.01" />
            </geometry>
            <origin xyz="0.098 0 -0.805" rpy="${PI/2} 0 0" />
        </collision>
    </link>

    <joint name="rev_base_link2_joint" type="continuous">
        <parent link="revolute_base_link" />
        <child link="link2" />
        <origin xyz="-0.100 -0.01 0.300" rpy="0 0 0.08" />  
        <axis xyz="0 1 0" />
    </joint>

    <link name="link3">
        <xacro:default_inertial mass="1.0" />
        <visual>
            <geometry>
                <mesh filename="package://arm_urdf/meshes/Link3_.stl" scale="0.01 0.01 0.01" />
            </geometry>
            <origin xyz="0.110 0 -3.15" rpy="${PI/2} 0 -0.02" />
        </visual>
        <collision>
            <geometry>
                <mesh filename="package://arm_urdf/meshes/Link3_.stl" scale="0.01 0.01 0.01" />
            </geometry>
            <origin xyz="0 0 0" rpy="0 0 0" />
        </collision>
    </link>

    <joint name="link2_link3_joint" type="continuous">
        <parent link="link2" />
        <child link="link3" />
        <origin xyz="-0.01 0 2.345" rpy="0 0 -0.05" />  
        <axis xyz="0 1 0" />
    </joint>

    <link name="link4">
        <xacro:default_inertial mass="1.0" />
        <visual>
            <geometry>
                <mesh filename="package://arm_urdf/meshes/Link4_.stl" scale="0.01 0.01 0.01" />
            </geometry>
            <origin xyz="0.098 0 -5.32" rpy="${PI/2} 0 0" />
        </visual>
        <collision>
            <geometry>
                <mesh filename="package://arm_urdf/meshes/Link4_.stl" scale="0.01 0.01 0.01" />
            </geometry>
            <origin xyz="0 0 0" rpy="0 0 0" />
        </collision>
    </link>

    <joint name="link3_link4_joint" type="continuous">
        <parent link="link3" />
        <child link="link4" />
        <origin xyz="0 -0.0055 2.168" rpy="0 0 0.05" />  
        <axis xyz="0 1 0" />
    </joint>

    <link name="link5">
        <xacro:default_inertial mass="1.0" />
        <visual>
            <geometry>
                <mesh filename="package://arm_urdf/meshes/Link5_.stl" scale="0.01 0.01 0.01" />
            </geometry>
            <origin xyz="0.098 0 -7.574" rpy="${PI/2} 0 0" />
        </visual>
        <collision>
            <geometry>
                <mesh filename="package://arm_urdf/meshes/Link5_.stl" scale="0.01 0.01 0.01" />
            </geometry>
            <origin xyz="0 0 0" rpy="0 0 0" />
        </collision>
    </link>

    <joint name="link4_link5_joint" type="continuous">
        <parent link="link4" />
        <child link="link5" />
        <origin xyz="0 0 2.253" rpy="0 0 0" />  
        <axis xyz="0 1 0" />
    </joint>

    <link name="gripper">
        <xacro:default_inertial mass="1.0" />
        <visual>
            <geometry>
                <mesh filename="package://arm_urdf/meshes/Link6_.stl" scale="0.01 0.01 0.01" />
            </geometry>
            <origin xyz="0.09 0.022 -8.285" rpy="${PI/2} 0 0" />
        </visual>
        <collision>
            <geometry>
                <mesh filename="package://arm_urdf/meshes/Link6_.stl" scale="0.01 0.01 0.01" />
            </geometry>
            <origin xyz="0 0 0" rpy="0 0 0" />
        </collision>
    </link>

    <joint name="link5_gripper_joint" type="continuous">
        <parent link="link5" />
        <child link="gripper" />
        <origin xyz="0.01 -0.033 0.72" rpy="0 0 0" />  
        <axis xyz="0 0 1" />
    </joint>

</robot>
